<sdf version='1.11'>
  <model name='mobile_robot'>
    <link name='base_link'>
      <inertial>
        <pose>0.0048076923076923088 0 0.005192307692307694 0 0 0</pose>
        <mass>10.4</mass>
        <inertia>
          <ixx>0.1072996153846154</ixx>
          <ixy>0</ixy>
          <ixz>-0.0063403846153846149</ixz>
          <iyy>0.1135592307692308</iyy>
          <iyz>0</iyz>
          <izz>0.1064596153846154</izz>
        </inertia>
      </inertial>
      <collision name='base_link_collision'>
        <pose>0 0 0 0 0 0</pose>
        <geometry>
          <box>
            <size>0.40000000000000002 0.29999999999999999 0.14999999999999999</size>
          </box>
        </geometry>
      </collision>
      <collision name='base_link_fixed_joint_lump__camera_link_collision_1'>
        <pose>0.10000000000000001 0 0.14999999999999999 0 0 0</pose>
        <geometry>
          <box>
            <size>0.059999999999999998 0.059999999999999998 0.040000000000000001</size>
          </box>
        </geometry>
      </collision>
      <collision name='base_link_fixed_joint_lump__lidar_link_collision_2'>
        <pose>0.14999999999999999 0 0.12 0 0 0</pose>
        <geometry>
          <cylinder>
            <length>0.050000000000000003</length>
            <radius>0.040000000000000001</radius>
          </cylinder>
        </geometry>
      </collision>
      <visual name='base_link_visual'>
        <pose>0 0 0 0 0 0</pose>
        <geometry>
          <box>
            <size>0.40000000000000002 0.29999999999999999 0.14999999999999999</size>
          </box>
        </geometry>
      </visual>
      <visual name='base_link_fixed_joint_lump__camera_link_visual_1'>
        <pose>0.10000000000000001 0 0.14999999999999999 0 0 0</pose>
        <geometry>
          <box>
            <size>0.059999999999999998 0.059999999999999998 0.040000000000000001</size>
          </box>
        </geometry>
      </visual>
      <visual name='base_link_fixed_joint_lump__lidar_link_visual_2'>
        <pose>0.14999999999999999 0 0.12 0 0 0</pose>
        <geometry>
          <cylinder>
            <length>0.050000000000000003</length>
            <radius>0.040000000000000001</radius>
          </cylinder>
        </geometry>
      </visual>
    </link>
    <joint name='left_wheel_joint' type='revolute'>
      <pose relative_to='base_link'>0 0.14999999999999999 -0.050000000000000003 0 0 0</pose>
      <parent>base_link</parent>
      <child>left_wheel</child>
      <axis>
        <xyz>0 1 0</xyz>
        <limit>
          <lower>-inf</lower>
    </frame>
    <frame name='laser_joint' attached_to='lidar_link'>
      <pose>0 0 0 0 0 0</pose>
    </frame>
    <frame name='laser_frame' attached_to='laser_joint'>
      <pose>0 0 0 0 0 0</pose>
    </frame>
    <frame name='lidar_joint' attached_to='base_link'>
      <pose>0.14999999999999999 0 0.12 0 0 0</pose>
    </frame>
    <frame name='lidar_link' attached_to='lidar_joint'>
      <pose>0 0 0 0 0 0</pose>
    </frame>
      <plugin
      filename="gz-sim-diff-drive-system"
      name="gz::sim::systems::DiffDrive">

      <left_joint>left_wheel_joint</left_joint>
      <right_joint>right_wheel_joint</right_joint>

      <wheel_separation>0.30</wheel_separation>
      <wheel_radius>0.05</wheel_radius>

      <topic>cmd_vel</topic>

      <odom_topic>odom</odom_topic>

      <frame_id>odom</frame_id>
      <child_frame_id>base_link</child_frame_id>

      <publish_tf>true</publish_tf>
      <publish_odom>true</publish_odom>

    </plugin>

  </model>
</sdf>
    </frame>
    <frame name='laser_joint' attached_to='lidar_link'>
      <pose>0 0 0 0 0 0</pose>
    </frame>
    <frame name='laser_frame' attached_to='laser_joint'>
      <pose>0 0 0 0 0 0</pose>
    </frame>
    <frame name='lidar_joint' attached_to='base_link'>
      <pose>0.14999999999999999 0 0.12 0 0 0</pose>
    </frame>
    <frame name='lidar_link' attached_to='lidar_joint'>
      <pose>0 0 0 0 0 0</pose>
    </frame>
      <plugin
      filename="gz-sim-diff-drive-system"
      name="gz::sim::systems::DiffDrive">

      <left_joint>left_wheel_joint</left_joint>
      <right_joint>right_wheel_joint</right_joint>

      <wheel_separation>0.30</wheel_separation>
      <wheel_radius>0.05</wheel_radius>

      <topic>cmd_vel</topic>

      <odom_topic>odom</odom_topic>

      <frame_id>odom</frame_id>
      <child_frame_id>base_link</child_frame_id>

      <publish_tf>true</publish_tf>
      <publish_odom>true</publish_odom>

    </plugin>

  </model>
</sdf>
          <upper>inf</upper>
        </limit>
        <dynamics>
          <spring_reference>0</spring_reference>
          <spring_stiffness>0</spring_stiffness>
        </dynamics>
      </axis>
    </joint>
    <link name='left_wheel'>
      <pose relative_to='left_wheel_joint'>0 0 0 0 0 0</pose>
      <inertial>
        <pose>0 0 0 0 0 0</pose>
        <mass>0.5</mass>
        <inertia>
          <ixx>0.001</ixx>
          <ixy>0</ixy>
          <ixz>0</ixz>
          <iyy>0.001</iyy>
          <iyz>0</iyz>
          <izz>0.001</izz>
        </inertia>
      </inertial>
      <collision name='left_wheel_collision'>
        <pose>0 0 0 1.5708 0 0</pose>
        <geometry>
          <cylinder>
            <length>0.029999999999999999</length>
            <radius>0.050000000000000003</radius>
          </cylinder>
        </geometry>
      </collision>
      <visual name='left_wheel_visual'>
        <pose>0 0 0 1.5708 0 0</pose>
        <geometry>
          <cylinder>
            <length>0.029999999999999999</length>
            <radius>0.050000000000000003</radius>
          </cylinder>
        </geometry>
      </visual>
    </link>
    <joint name='right_wheel_joint' type='revolute'>
      <pose relative_to='base_link'>0 -0.14999999999999999 -0.050000000000000003 0 0 0</pose>
      <parent>base_link</parent>
      <child>right_wheel</child>
      <axis>
        <xyz>0 1 0</xyz>
        <limit>
          <lower>-inf</lower>
          <upper>inf</upper>
        </limit>
        <dynamics>
          <spring_reference>0</spring_reference>
          <spring_stiffness>0</spring_stiffness>
        </dynamics>
      </axis>
    </joint>
    <link name='right_wheel'>
      <pose relative_to='right_wheel_joint'>0 0 0 0 0 0</pose>
      <inertial>
        <pose>0 0 0 0 0 0</pose>
        <mass>0.5</mass>
        <inertia>
          <ixx>0.001</ixx>
          <ixy>0</ixy>
          <ixz>0</ixz>
          <iyy>0.001</iyy>
          <iyz>0</iyz>
          <izz>0.001</izz>
        </inertia>
      </inertial>
      <collision name='right_wheel_collision'>
        <pose>0 0 0 1.5708 0 0</pose>
        <geometry>
          <cylinder>
            <length>0.029999999999999999</length>
            <radius>0.050000000000000003</radius>
          </cylinder>
        </geometry>
      </collision>
      <visual name='right_wheel_visual'>
        <pose>0 0 0 1.5708 0 0</pose>
        <geometry>
          <cylinder>
            <length>0.029999999999999999</length>
            <radius>0.050000000000000003</radius>
          </cylinder>
        </geometry>
      </visual>
    </link>
    <frame name='camera_optical_joint' attached_to='camera_link'>
      <pose>0 0 0 -1.5708 -5.5511151231257827e-17 -1.5708</pose>
    </frame>
    <frame name='camera_optical_frame' attached_to='camera_optical_joint'>
      <pose>0 0 0 0 0 0</pose>
    </frame>
    <frame name='camera_joint' attached_to='base_link'>
      <pose>0.10000000000000001 0 0.14999999999999999 0 0 0</pose>
    </frame>
    <frame name='camera_link' attached_to='camera_joint'>
      <pose>0 0 0 0 0 0</pose>
    </frame>
    <frame name='laser_joint' attached_to='lidar_link'>
      <pose>0 0 0 0 0 0</pose>
    </frame>
    <frame name='laser_frame' attached_to='laser_joint'>
      <pose>0 0 0 0 0 0</pose>
    </frame>
    <frame name='lidar_joint' attached_to='base_link'>
      <pose>0.14999999999999999 0 0.12 0 0 0</pose>
    </frame>
    <frame name='lidar_link' attached_to='lidar_joint'>
      <pose>0 0 0 0 0 0</pose>
    </frame>
      <plugin
      filename="gz-sim-diff-drive-system"
      name="gz::sim::systems::DiffDrive">

      <left_joint>left_wheel_joint</left_joint>
      <right_joint>right_wheel_joint</right_joint>

      <wheel_separation>0.30</wheel_separation>
      <wheel_radius>0.05</wheel_radius>

      <topic>cmd_vel</topic>

      <odom_topic>odom</odom_topic>

      <frame_id>odom</frame_id>
      <child_frame_id>base_link</child_frame_id>

      <publish_tf>true</publish_tf>
      <publish_odom>true</publish_odom>

    </plugin>

  </model>
</sdf>
